Workbook

Sheet Challenge
B5: GoSkills Excel Challenge 48
B8: For this challenge, you'll take on these Excel missions:
C11: Write a formula in cell H2 of the Data worksheet to display the availability of each book based on the information in the Transactions worksheet.
C12: Create a formula to return the Student Name in cell B2 of the Check worksheet.
C13: Write a formula in cell C2 of the Check worksheet to show the number of books borrowed by the selected student.
C14: Develop a formula to calculate overdue fines for the selected student in cell D2 of the Check worksheet.
C15: Write a formula in cell E2 of the Check worksheet to display the remaining borrowing allowance for the selected student, considering a maximum limit of 5 books.
C16: Note that if a student has overdue fines, they should not be allowed to borrow any more books, even if they are still within their borrowing limit.
C17: Create a formula in cell H2 of the Check worksheet to return the title of the selected book.
C18: Write a formula in cell I2 of the Check worksheet to display the availability of the selected book based on its remaining copies.
C19: Develop a formula in cell J2 of the Check worksheet to return the earliest due date for the selected book if no copies are available.
C20: In column G of the Transactions worksheet, calculate the Due Date for each borrowed book based on a 21-day loan period.
C21: Calculate the number of overdue days for each loan by comparing the Return Date and Due Date in column I of the Transactions worksheet.
C22: Calculate overdue fines by charging $1 for each overdue day in column J of the Transactions worksheet.

Sheet Data
A1: Student ID | B1: Student Name | D1: Book ID | E1: Title | F1: Author | G1: Number of Copies | H1: Status
A2: ID0001 | B2: Frank Clark Jr. | D2: B00001 | E2: Child Figure Up | F2: Kelsey Marquez | G2: 5 | H2: =IF(COUNTIFS(Transactions[Book ID],Books[[#This Row],[Book ID]],Transactions[Return Date],"")<Books[[#This Row],[Number of Copies]],"Available","Not Available") -> Available
A3: ID0002 | B3: Robert Patel | D3: B00002 | E3: Ready Firm | F3: James Snow | G3: 4 | H3: =IF(COUNTIFS(Transactions[Book ID],Books[[#This Row],[Book ID]],Transactions[Return Date],"")<Books[[#This Row],[Number of Copies]],"Available","Not Available") -> Available
A4: ID0003 | B4: Joshua Moran | D4: B00003 | E4: Yet Dinner | F4: Michael Burke | G4: 5 | H4: =IF(COUNTIFS(Transactions[Book ID],Books[[#This Row],[Book ID]],Transactions[Return Date],"")<Books[[#This Row],[Number of Copies]],"Available","Not Available") -> Available
A5: ID0004 | B5: Tina Willis | D5: B00004 | E5: Policy Behind Charge Shoulder | F5: Ann Wagner | G5: 5 | H5: =IF(COUNTIFS(Transactions[Book ID],Books[[#This Row],[Book ID]],Transactions[Return Date],"")<Books[[#This Row],[Number of Copies]],"Available","Not Available") -> Available
A6: ID0005 | B6: Sandra Fields | D6: B00005 | E6: Form Method Task | F6: Keith Mitchell | G6: 5 | H6: =IF(COUNTIFS(Transactions[Book ID],Books[[#This Row],[Book ID]],Transactions[Return Date],"")<Books[[#This Row],[Number of Copies]],"Available","Not Available") -> Available
A7: ID0006 | B7: William Wolfe | D7: B00006 | E7: Politics Car Sure | F7: Ariel Hubbard | G7: 5 | H7: =IF(COUNTIFS(Transactions[Book ID],Books[[#This Row],[Book ID]],Transactions[Return Date],"")<Books[[#This Row],[Number of Copies]],"Available","Not Available") -> Available
A8: ID0007 | B8: Nicholas Wyatt | D8: B00007 | E8: Ball Social | F8: Kyle Cross | G8: 4 | H8: =IF(COUNTIFS(Transactions[Book ID],Books[[#This Row],[Book ID]],Transactions[Return Date],"")<Books[[#This Row],[Number of Copies]],"Available","Not Available") -> Available
A9: ID0008 | B9: Alisha Miller | D9: B00008 | E9: Close Music Direction | F9: Helen Watson | G9: 3 | H9: =IF(COUNTIFS(Transactions[Book ID],Books[[#This Row],[Book ID]],Transactions[Return Date],"")<Books[[#This Row],[Number of Copies]],"Available","Not Available") -> Available
A10: ID0009 | B10: Tracy Abbott | D10: B00009 | E10: Information Eat | F10: Nicole Martinez | G10: 5 | H10: =IF(COUNTIFS(Transactions[Book ID],Books[[#This Row],[Book ID]],Transactions[Return Date],"")<Books[[#This Row],[Number of Copies]],"Available","Not Available") -> Available
A11: ID0010 | B11: Erin Chandler | D11: B00010 | E11: Term Heavy | F11: David Lopez | G11: 4 | H11: =IF(COUNTIFS(Transactions[Book ID],Books[[#This Row],[Book ID]],Transactions[Return Date],"")<Books[[#This Row],[Number of Copies]],"Available","Not Available") -> Available
A12: ID0011 | B12: Jeffrey Garrett | D12: B00011 | E12: Pattern Travel Parent | F12: Zoe Ingram | G12: 5 | H12: =IF(COUNTIFS(Transactions[Book ID],Books[[#This Row],[Book ID]],Transactions[Return Date],"")<Books[[#This Row],[Number of Copies]],"Available","Not Available") -> Available
A13: ID0012 | B13: Tracy Sullivan | D13: B00012 | E13: Fine Benefit Must | F13: John Jackson | G13: 5 | H13: =IF(COUNTIFS(Transactions[Book ID],Books[[#This Row],[Book ID]],Transactions[Return Date],"")<Books[[#This Row],[Number of Copies]],"Available","Not Available") -> Available
... A101: ID0100 | B101: Alyssa Davis | D101: B00100 | E101: Hour Wall Nice | F101: Angela Torres | G101: 5 | H101: =IF(COUNTIFS(Transactions[Book ID],Books[[#This Row],[Book ID]],Transactions[Return Date],"")<Books[[#This Row],[Number of Copies]],"Available","Not Available") -> Available
D102: B00101 | E102: Will Discover Market | F102: David Potter | G102: 4 | H102: =IF(COUNTIFS(Transactions[Book ID],Books[[#This Row],[Book ID]],Transactions[Return Date],"")<Books[[#This Row],[Number of Copies]],"Available","Not Available") -> Available
D103: B00102 | E103: Develop Around | F103: Joseph Lewis | G103: 4 | H103: =IF(COUNTIFS(Transactions[Book ID],Books[[#This Row],[Book ID]],Transactions[Return Date],"")<Books[[#This Row],[Number of Copies]],"Available","Not Available") -> Available
D104: B00103 | E104: College Coach Bad | F104: Michael Meyer III | G104: 5 | H104: =IF(COUNTIFS(Transactions[Book ID],Books[[#This Row],[Book ID]],Transactions[Return Date],"")<Books[[#This Row],[Number of Copies]],"Available","Not Available") -> Available
D105: B00104 | E105: Write Class | F105: Marissa Velazquez | G105: 3 | H105: =IF(COUNTIFS(Transactions[Book ID],Books[[#This Row],[Book ID]],Transactions[Return Date],"")<Books[[#This Row],[Number of Copies]],"Available","Not Available") -> Available
D106: B00105 | E106: Better Forward View | F106: Albert Hall | G106: 4 | H106: =IF(COUNTIFS(Transactions[Book ID],Books[[#This Row],[Book ID]],Transactions[Return Date],"")<Books[[#This Row],[Number of Copies]],"Available","Not Available") -> Available
D107: B00106 | E107: Return Authority Question | F107: Miranda Blankenship | G107: 3 | H107: =IF(COUNTIFS(Transactions[Book ID],Books[[#This Row],[Book ID]],Transactions[Return Date],"")<Books[[#This Row],[Number of Copies]],"Available","Not Available") -> Available
D108: B00107 | E108: Here Glass Believe | F108: Kathleen Shelton | G108: 3 | H108: =IF(COUNTIFS(Transactions[Book ID],Books[[#This Row],[Book ID]],Transactions[Return Date],"")<Books[[#This Row],[Number of Copies]],"Available","Not Available") -> Available
D109: B00108 | E109: Old Rich | F109: Connie Flores | G109: 5 | H109: =IF(COUNTIFS(Transactions[Book ID],Books[[#This Row],[Book ID]],Transactions[Return Date],"")<Books[[#This Row],[Number of Copies]],"Available","Not Available") -> Available
D110: B00109 | E110: Somebody Opportunity | F110: Justin Solis | G110: 3 | H110: =IF(COUNTIFS(Transactions[Book ID],Books[[#This Row],[Book ID]],Transactions[Return Date],"")<Books[[#This Row],[Number of Copies]],"Available","Not Available") -> Available
D111: B00110 | E111: Issue Act | F111: Tiffany Taylor | G111: 4 | H111: =IF(COUNTIFS(Transactions[Book ID],Books[[#This Row],[Book ID]],Transactions[Return Date],"")<Books[[#This Row],[Number of Copies]],"Available","Not Available") -> Available
D112: B00111 | E112: Mean Analysis Behind | F112: Robert Hernandez | G112: 3 | H112: =IF(COUNTIFS(Transactions[Book ID],Books[[#This Row],[Book ID]],Transactions[Return Date],"")<Books[[#This Row],[Number of Copies]],"Available","Not Available") -> Available
D113: B00112 | E113: Radio Wait Available Author | F113: Jerome Wood | G113: 5 | H113: =IF(COUNTIFS(Transactions[Book ID],Books[[#This Row],[Book ID]],Transactions[Return Date],"")<Books[[#This Row],[Number of Copies]],"Available","Not Available") -> Available
... D121: B00120 | E121: Music Simply | F121: Dr. Lisa Turner DVM | G121: 5 | H121: =IF(COUNTIFS(Transactions[Book ID],Books[[#This Row],[Book ID]],Transactions[Return Date],"")<Books[[#This Row],[Number of Copies]],"Available","Not Available") -> Available

Sheet Check
A1: Student ID | B1: Student Name | C1: Total Books Borrowed | D1: Overdue Fines | E1: Remaining Allotment | G1: Book ID | H1: Title | I1: Availability | J1: Due Date
A2: ID0062 | B2: =_xlfn.XLOOKUP(A2,Students[Student ID],Students[Student Name]) -> Kenneth Mitchell Jr. | C2: =COUNTIFS(Transactions[Student Name],B2,Transactions[Return Date],"") -> 1 | D2: =_xlfn.XLOOKUP(A2,Transactions[Student ID],Transactions[Overdue Fines]) -> 0 | E2: =IF(OR(D2>0,C2=5),0,5-C2) -> 4 | G2: B00003 | H2: =_xlfn.XLOOKUP(G2,Books[Book ID],Books[Title]) -> Yet Dinner | I2: =_xlfn.XLOOKUP(H2,Books[Title],Books[Status]) -> Available | J2: {=IF(I2="Not Available",_xlfn._xlws.FILTER(Transactions[Due Date],(Transactions[Book ID]=Check!G2)*(Transactions[Due Date]>=TODAY()),"Overdue"),"")}

Sheet Transactions
A1: Transaction ID | B1: Student ID | C1: Student Name | D1: Book ID | E1: Title | F1: Borrow Date | G1: Due Date | H1: Return Date | I1: Overdue Days | J1: Overdue Fines
A2: T00148 | B2: ID0100 | C2: =VLOOKUP(B2,Data!$A$2:$B$101,2,0) -> Alyssa Davis | D2: B00002 | E2: =VLOOKUP(D2,Data!$D$2:$E$121,2,0) -> Ready Firm | F2: 45333 | G2: =Transactions[[#This Row],[Borrow Date]]+21 -> 45354 | H2: 45348 | I2: {=_xlfn.IFS(Transactions[[#This Row],[Return Date]]<=Transactions[[#This Row],[Due Date]],0,AND(Transactions[[#This Row],[Return Date]]="",TODAY()<=Transactions[[#This Row],[Due Date]]),0,Transactions[[#This Row],[Return Date]]>Transactions[[#This Row],[Due Date]],Transactions[[#This Row],[Return Date]]-Transactions[[#This Row],[Due Date]],AND(Transactions[[#This Row],[Return Date]]="",TODAY()>Transactions[[#This Row],[Due Date]]),TODAY()-Transactions[[#This Row],[Due Date]])} -> 0 | J2: =Transactions[[#This Row],[Overdue Days]] -> 0
A3: T00223 | B3: ID0030 | C3: =VLOOKUP(B3,Data!$A$2:$B$101,2,0) -> John Wright | D3: B00002 | E3: =VLOOKUP(D3,Data!$D$2:$E$121,2,0) -> Ready Firm | F3: 45651 | G3: =Transactions[[#This Row],[Borrow Date]]+21 -> 45672 | I3: {=_xlfn.IFS(Transactions[[#This Row],[Return Date]]<=Transactions[[#This Row],[Due Date]],0,AND(Transactions[[#This Row],[Return Date]]="",TODAY()<=Transactions[[#This Row],[Due Date]]),0,Transactions[[#This Row],[Return Date]]>Transactions[[#This Row],[Due Date]],Transactions[[#This Row],[Return Date]]-Transactions[[#This Row],[Due Date]],AND(Transactions[[#This Row],[Return Date]]="",TODAY()>Transactions[[#This Row],[Due Date]]),TODAY()-Transactions[[#This Row],[Due Date]])} -> #VALUE! | J3: =Transactions[[#This Row],[Overdue Days]] -> #VALUE!
A4: T00230 | B4: ID0088 | C4: =VLOOKUP(B4,Data!$A$2:$B$101,2,0) -> Cheyenne Garcia | D4: B00002 | E4: =VLOOKUP(D4,Data!$D$2:$E$121,2,0) -> Ready Firm | F4: 45377 | G4: =Transactions[[#This Row],[Borrow Date]]+21 -> 45398 | H4: 45401 | I4: {=_xlfn.IFS(Transactions[[#This Row],[Return Date]]<=Transactions[[#This Row],[Due Date]],0,AND(Transactions[[#This Row],[Return Date]]="",TODAY()<=Transactions[[#This Row],[Due Date]]),0,Transactions[[#This Row],[Return Date]]>Transactions[[#This Row],[Due Date]],Transactions[[#This Row],[Return Date]]-Transactions[[#This Row],[Due Date]],AND(Transactions[[#This Row],[Return Date]]="",TODAY()>Transactions[[#This Row],[Due Date]]),TODAY()-Transactions[[#This Row],[Due Date]])} -> 3 | J4: =Transactions[[#This Row],[Overdue Days]] -> 3
A5: T00049 | B5: ID0044 | C5: =VLOOKUP(B5,Data!$A$2:$B$101,2,0) -> Patrick Garcia | D5: B00003 | E5: =VLOOKUP(D5,Data!$D$2:$E$121,2,0) -> Yet Dinner | F5: 45465 | G5: =Transactions[[#This Row],[Borrow Date]]+21 -> 45486 | H5: 45488 | I5: {=_xlfn.IFS(Transactions[[#This Row],[Return Date]]<=Transactions[[#This Row],[Due Date]],0,AND(Transactions[[#This Row],[Return Date]]="",TODAY()<=Transactions[[#This Row],[Due Date]]),0,Transactions[[#This Row],[Return Date]]>Transactions[[#This Row],[Due Date]],Transactions[[#This Row],[Return Date]]-Transactions[[#This Row],[Due Date]],AND(Transactions[[#This Row],[Return Date]]="",TODAY()>Transactions[[#This Row],[Due Date]]),TODAY()-Transactions[[#This Row],[Due Date]])} -> 2 | J5: =Transactions[[#This Row],[Overdue Days]] -> 2
A6: T00110 | B6: ID0010 | C6: =VLOOKUP(B6,Data!$A$2:$B$101,2,0) -> Erin Chandler | D6: B00003 | E6: =VLOOKUP(D6,Data!$D$2:$E$121,2,0) -> Yet Dinner | F6: 45523 | G6: =Transactions[[#This Row],[Borrow Date]]+21 -> 45544 | H6: 45549 | I6: {=_xlfn.IFS(Transactions[[#This Row],[Return Date]]<=Transactions[[#This Row],[Due Date]],0,AND(Transactions[[#This Row],[Return Date]]="",TODAY()<=Transactions[[#This Row],[Due Date]]),0,Transactions[[#This Row],[Return Date]]>Transactions[[#This Row],[Due Date]],Transactions[[#This Row],[Return Date]]-Transactions[[#This Row],[Due Date]],AND(Transactions[[#This Row],[Return Date]]="",TODAY()>Transactions[[#This Row],[Due Date]]),TODAY()-Transactions[[#This Row],[Due Date]])} -> 5 | J6: =Transactions[[#This Row],[Overdue Days]] -> 5
A7: T00127 | B7: ID0089 | C7: =VLOOKUP(B7,Data!$A$2:$B$101,2,0) -> Edward Price | D7: B00003 | E7: =VLOOKUP(D7,Data!$D$2:$E$121,2,0) -> Yet Dinner | F7: 45523 | G7: =Transactions[[#This Row],[Borrow Date]]+21 -> 45544 | H7: 45538 | I7: {=_xlfn.IFS(Transactions[[#This Row],[Return Date]]<=Transactions[[#This Row],[Due Date]],0,AND(Transactions[[#This Row],[Return Date]]="",TODAY()<=Transactions[[#This Row],[Due Date]]),0,Transactions[[#This Row],[Return Date]]>Transactions[[#This Row],[Due Date]],Transactions[[#This Row],[Return Date]]-Transactions[[#This Row],[Due Date]],AND(Transactions[[#This Row],[Return Date]]="",TODAY()>Transactions[[#This Row],[Due Date]]),TODAY()-Transactions[[#This Row],[Due Date]])} -> 0 | J7: =Transactions[[#This Row],[Overdue Days]] -> 0
A8: T00134 | B8: ID0078 | C8: =VLOOKUP(B8,Data!$A$2:$B$101,2,0) -> Christopher Fleming | D8: B00003 | E8: =VLOOKUP(D8,Data!$D$2:$E$121,2,0) -> Yet Dinner | F8: 45478 | G8: =Transactions[[#This Row],[Borrow Date]]+21 -> 45499 | H8: 45498 | I8: {=_xlfn.IFS(Transactions[[#This Row],[Return Date]]<=Transactions[[#This Row],[Due Date]],0,AND(Transactions[[#This Row],[Return Date]]="",TODAY()<=Transactions[[#This Row],[Due Date]]),0,Transactions[[#This Row],[Return Date]]>Transactions[[#This Row],[Due Date]],Transactions[[#This Row],[Return Date]]-Transactions[[#This Row],[Due Date]],AND(Transactions[[#This Row],[Return Date]]="",TODAY()>Transactions[[#This Row],[Due Date]]),TODAY()-Transactions[[#This Row],[Due Date]])} -> 0 | J8: =Transactions[[#This Row],[Overdue Days]] -> 0
A9: T00229 | B9: ID0089 | C9: =VLOOKUP(B9,Data!$A$2:$B$101,2,0) -> Edward Price | D9: B00003 | E9: =VLOOKUP(D9,Data!$D$2:$E$121,2,0) -> Yet Dinner | F9: 45621 | G9: =Transactions[[#This Row],[Borrow Date]]+21 -> 45642 | H9: 45646 | I9: {=_xlfn.IFS(Transactions[[#This Row],[Return Date]]<=Transactions[[#This Row],[Due Date]],0,AND(Transactions[[#This Row],[Return Date]]="",TODAY()<=Transactions[[#This Row],[Due Date]]),0,Transactions[[#This Row],[Return Date]]>Transactions[[#This Row],[Due Date]],Transactions[[#This Row],[Return Date]]-Transactions[[#This Row],[Due Date]],AND(Transactions[[#This Row],[Return Date]]="",TODAY()>Transactions[[#This Row],[Due Date]]),TODAY()-Transactions[[#This Row],[Due Date]])} -> 4 | J9: =Transactions[[#This Row],[Overdue Days]] -> 4
A10: T00243 | B10: ID0017 | C10: =VLOOKUP(B10,Data!$A$2:$B$101,2,0) -> Katelyn Flores | D10: B00004 | E10: =VLOOKUP(D10,Data!$D$2:$E$121,2,0) -> Policy Behind Charge Shoulder | F10: 45491 | G10: =Transactions[[#This Row],[Borrow Date]]+21 -> 45512 | H10: 45514 | I10: {=_xlfn.IFS(Transactions[[#This Row],[Return Date]]<=Transactions[[#This Row],[Due Date]],0,AND(Transactions[[#This Row],[Return Date]]="",TODAY()<=Transactions[[#This Row],[Due Date]]),0,Transactions[[#This Row],[Return Date]]>Transactions[[#This Row],[Due Date]],Transactions[[#This Row],[Return Date]]-Transactions[[#This Row],[Due Date]],AND(Transactions[[#This Row],[Return Date]]="",TODAY()>Transactions[[#This Row],[Due Date]]),TODAY()-Transactions[[#This Row],[Due Date]])} -> 2 | J10: =Transactions[[#This Row],[Overdue Days]] -> 2
A11: T00249 | B11: ID0037 | C11: =VLOOKUP(B11,Data!$A$2:$B$101,2,0) -> Tommy Miller | D11: B00004 | E11: =VLOOKUP(D11,Data!$D$2:$E$121,2,0) -> Policy Behind Charge Shoulder | F11: 45483 | G11: =Transactions[[#This Row],[Borrow Date]]+21 -> 45504 | H11: 45500 | I11: {=_xlfn.IFS(Transactions[[#This Row],[Return Date]]<=Transactions[[#This Row],[Due Date]],0,AND(Transactions[[#This Row],[Return Date]]="",TODAY()<=Transactions[[#This Row],[Due Date]]),0,Transactions[[#This Row],[Return Date]]>Transactions[[#This Row],[Due Date]],Transactions[[#This Row],[Return Date]]-Transactions[[#This Row],[Due Date]],AND(Transactions[[#This Row],[Return Date]]="",TODAY()>Transactions[[#This Row],[Due Date]]),TODAY()-Transactions[[#This Row],[Due Date]])} -> 0 | J11: =Transactions[[#This Row],[Overdue Days]] -> 0
A12: T00091 | B12: ID0059 | C12: =VLOOKUP(B12,Data!$A$2:$B$101,2,0) -> Dillon Payne | D12: B00005 | E12: =VLOOKUP(D12,Data!$D$2:$E$121,2,0) -> Form Method Task | F12: 45585 | G12: =Transactions[[#This Row],[Borrow Date]]+21 -> 45606 | H12: 45600 | I12: {=_xlfn.IFS(Transactions[[#This Row],[Return Date]]<=Transactions[[#This Row],[Due Date]],0,AND(Transactions[[#This Row],[Return Date]]="",TODAY()<=Transactions[[#This Row],[Due Date]]),0,Transactions[[#This Row],[Return Date]]>Transactions[[#This Row],[Due Date]],Transactions[[#This Row],[Return Date]]-Transactions[[#This Row],[Due Date]],AND(Transactions[[#This Row],[Return Date]]="",TODAY()>Transactions[[#This Row],[Due Date]]),TODAY()-Transactions[[#This Row],[Due Date]])} -> 0 | J12: =Transactions[[#This Row],[Overdue Days]] -> 0
A13: T00001 | B13: ID0049 | C13: =VLOOKUP(B13,Data!$A$2:$B$101,2,0) -> Susan Moreno | D13: B00006 | E13: =VLOOKUP(D13,Data!$D$2:$E$121,2,0) -> Politics Car Sure | F13: 45653 | G13: =Transactions[[#This Row],[Borrow Date]]+21 -> 45674 | I13: {=_xlfn.IFS(Transactions[[#This Row],[Return Date]]<=Transactions[[#This Row],[Due Date]],0,AND(Transactions[[#This Row],[Return Date]]="",TODAY()<=Transactions[[#This Row],[Due Date]]),0,Transactions[[#This Row],[Return Date]]>Transactions[[#This Row],[Due Date]],Transactions[[#This Row],[Return Date]]-Transactions[[#This Row],[Due Date]],AND(Transactions[[#This Row],[Return Date]]="",TODAY()>Transactions[[#This Row],[Due Date]]),TODAY()-Transactions[[#This Row],[Due Date]])} -> #VALUE! | J13: =Transactions[[#This Row],[Overdue Days]] -> #VALUE!
A14: T00080 | B14: ID0020 | C14: =VLOOKUP(B14,Data!$A$2:$B$101,2,0) -> Jesse Kennedy | D14: B00007 | E14: =VLOOKUP(D14,Data!$D$2:$E$121,2,0) -> Ball Social | F14: 45571 | G14: =Transactions[[#This Row],[Borrow Date]]+21 -> 45592 | H14: 45596 | I14: {=_xlfn.IFS(Transactions[[#This Row],[Return Date]]<=Transactions[[#This Row],[Due Date]],0,AND(Transactions[[#This Row],[Return Date]]="",TODAY()<=Transactions[[#This Row],[Due Date]]),0,Transactions[[#This Row],[Return Date]]>Transactions[[#This Row],[Due Date]],Transactions[[#This Row],[Return Date]]-Transactions[[#This Row],[Due Date]],AND(Transactions[[#This Row],[Return Date]]="",TODAY()>Transactions[[#This Row],[Due Date]]),TODAY()-Transactions[[#This Row],[Due Date]])} -> 4 | J14: =Transactions[[#This Row],[Overdue Days]] -> 4
A15: T00139 | B15: ID0021 | C15: =VLOOKUP(B15,Data!$A$2:$B$101,2,0) -> David Lopez | D15: B00007 | E15: =VLOOKUP(D15,Data!$D$2:$E$121,2,0) -> Ball Social | F15: 45454 | G15: =Transactions[[#This Row],[Borrow Date]]+21 -> 45475 | H15: 45477 | I15: {=_xlfn.IFS(Transactions[[#This Row],[Return Date]]<=Transactions[[#This Row],[Due Date]],0,AND(Transactions[[#This Row],[Return Date]]="",TODAY()<=Transactions[[#This Row],[Due Date]]),0,Transactions[[#This Row],[Return Date]]>Transactions[[#This Row],[Due Date]],Transactions[[#This Row],[Return Date]]-Transactions[[#This Row],[Due Date]],AND(Transactions[[#This Row],[Return Date]]="",TODAY()>Transactions[[#This Row],[Due Date]]),TODAY()-Transactions[[#This Row],[Due Date]])} -> 2 | J15: =Transactions[[#This Row],[Overdue Days]] -> 2
A16: T00216 | B16: ID0060 | C16: =VLOOKUP(B16,Data!$A$2:$B$101,2,0) -> Scott Howell | D16: B00007 | E16: =VLOOKUP(D16,Data!$D$2:$E$121,2,0) -> Ball Social | F16: 45362 | G16: =Transactions[[#This Row],[Borrow Date]]+21 -> 45383 | H16: 45388 | I16: {=_xlfn.IFS(Transactions[[#This Row],[Return Date]]<=Transactions[[#This Row],[Due Date]],0,AND(Transactions[[#This Row],[Return Date]]="",TODAY()<=Transactions[[#This Row],[Due Date]]),0,Transactions[[#This Row],[Return Date]]>Transactions[[#This Row],[Due Date]],Transactions[[#This Row],[Return Date]]-Transactions[[#This Row],[Due Date]],AND(Transactions[[#This Row],[Return Date]]="",TODAY()>Transactions[[#This Row],[Due Date]]),TODAY()-Transactions[[#This Row],[Due Date]])} -> 5 | J16: =Transactions[[#This Row],[Overdue Days]] -> 5
A17: T00028 | B17: ID0032 | C17: =VLOOKUP(B17,Data!$A$2:$B$101,2,0) -> Jason Oconnor | D17: B00008 | E17: =VLOOKUP(D17,Data!$D$2:$E$121,2,0) -> Close Music Direction | F17: 45653 | G17: =Transactions[[#This Row],[Borrow Date]]+21 -> 45674 | I17: {=_xlfn.IFS(Transactions[[#This Row],[Return Date]]<=Transactions[[#This Row],[Due Date]],0,AND(Transactions[[#This Row],[Return Date]]="",TODAY()<=Transactions[[#This Row],[Due Date]]),0,Transactions[[#This Row],[Return Date]]>Transactions[[#This Row],[Due Date]],Transactions[[#This Row],[Return Date]]-Transactions[[#This Row],[Due Date]],AND(Transactions[[#This Row],[Return Date]]="",TODAY()>Transactions[[#This Row],[Due Date]]),TODAY()-Transactions[[#This Row],[Due Date]])} -> #VALUE! | J17: =Transactions[[#This Row],[Overdue Days]] -> #VALUE!
A18: T00156 | B18: ID0095 | C18: =VLOOKUP(B18,Data!$A$2:$B$101,2,0) -> Darlene Perry | D18: B00008 | E18: =VLOOKUP(D18,Data!$D$2:$E$121,2,0) -> Close Music Direction | F18: 45507 | G18: =Transactions[[#This Row],[Borrow Date]]+21 -> 45528 | H18: 45528 | I18: {=_xlfn.IFS(Transactions[[#This Row],[Return Date]]<=Transactions[[#This Row],[Due Date]],0,AND(Transactions[[#This Row],[Return Date]]="",TODAY()<=Transactions[[#This Row],[Due Date]]),0,Transactions[[#This Row],[Return Date]]>Transactions[[#This Row],[Due Date]],Transactions[[#This Row],[Return Date]]-Transactions[[#This Row],[Due Date]],AND(Transactions[[#This Row],[Return Date]]="",TODAY()>Transactions[[#This Row],[Due Date]]),TODAY()-Transactions[[#This Row],[Due Date]])} -> 0 | J18: =Transactions[[#This Row],[Overdue Days]] -> 0
A19: T00043 | B19: ID0096 | C19: =VLOOKUP(B19,Data!$A$2:$B$101,2,0) -> Amber Wright | D19: B00009 | E19: =VLOOKUP(D19,Data!$D$2:$E$121,2,0) -> Information Eat | F19: 45579 | G19: =Transactions[[#This Row],[Borrow Date]]+21 -> 45600 | H19: 45596 | I19: {=_xlfn.IFS(Transactions[[#This Row],[Return Date]]<=Transactions[[#This Row],[Due Date]],0,AND(Transactions[[#This Row],[Return Date]]="",TODAY()<=Transactions[[#This Row],[Due Date]]),0,Transactions[[#This Row],[Return Date]]>Transactions[[#This Row],[Due Date]],Transactions[[#This Row],[Return Date]]-Transactions[[#This Row],[Due Date]],AND(Transactions[[#This Row],[Return Date]]="",TODAY()>Transactions[[#This Row],[Due Date]]),TODAY()-Transactions[[#This Row],[Due Date]])} -> 0 | J19: =Transactions[[#This Row],[Overdue Days]] -> 0
A20: T00181 | B20: ID0056 | C20: =VLOOKUP(B20,Data!$A$2:$B$101,2,0) -> Ethan Sutton | D20: B00010 | E20: =VLOOKUP(D20,Data!$D$2:$E$121,2,0) -> Term Heavy | F20: 45601 | G20: =Transactions[[#This Row],[Borrow Date]]+21 -> 45622 | H20: 45627 | I20: {=_xlfn.IFS(Transactions[[#This Row],[Return Date]]<=Transactions[[#This Row],[Due Date]],0,AND(Transactions[[#This Row],[Return Date]]="",TODAY()<=Transactions[[#This Row],[Due Date]]),0,Transactions[[#This Row],[Return Date]]>Transactions[[#This Row],[Due Date]],Transactions[[#This Row],[Return Date]]-Transactions[[#This Row],[Due Date]],AND(Transactions[[#This Row],[Return Date]]="",TODAY()>Transactions[[#This Row],[Due Date]]),TODAY()-Transactions[[#This Row],[Due Date]])} -> 5 | J20: =Transactions[[#This Row],[Overdue Days]] -> 5
A21: T00161 | B21: ID0016 | C21: =VLOOKUP(B21,Data!$A$2:$B$101,2,0) -> Mark Hester | D21: B00011 | E21: =VLOOKUP(D21,Data!$D$2:$E$121,2,0) -> Pattern Travel Parent | F21: 45458 | G21: =Transactions[[#This Row],[Borrow Date]]+21 -> 45479 | H21: 45473 | I21: {=_xlfn.IFS(Transactions[[#This Row],[Return Date]]<=Transactions[[#This Row],[Due Date]],0,AND(Transactions[[#This Row],[Return Date]]="",TODAY()<=Transactions[[#This Row],[Due Date]]),0,Transactions[[#This Row],[Return Date]]>Transactions[[#This Row],[Due Date]],Transactions[[#This Row],[Return Date]]-Transactions[[#This Row],[Due Date]],AND(Transactions[[#This Row],[Return Date]]="",TODAY()>Transactions[[#This Row],[Due Date]]),TODAY()-Transactions[[#This Row],[Due Date]])} -> 0 | J21: =Transactions[[#This Row],[Overdue Days]] -> 0
A22: T00040 | B22: ID0054 | C22: =VLOOKUP(B22,Data!$A$2:$B$101,2,0) -> Karen Scott | D22: B00012 | E22: =VLOOKUP(D22,Data!$D$2:$E$121,2,0) -> Fine Benefit Must | F22: 45556 | G22: =Transactions[[#This Row],[Borrow Date]]+21 -> 45577 | H22: 45571 | I22: {=_xlfn.IFS(Transactions[[#This Row],[Return Date]]<=Transactions[[#This Row],[Due Date]],0,AND(Transactions[[#This Row],[Return Date]]="",TODAY()<=Transactions[[#This Row],[Due Date]]),0,Transactions[[#This Row],[Return Date]]>Transactions[[#This Row],[Due Date]],Transactions[[#This Row],[Return Date]]-Transactions[[#This Row],[Due Date]],AND(Transactions[[#This Row],[Return Date]]="",TODAY()>Transactions[[#This Row],[Due Date]]),TODAY()-Transactions[[#This Row],[Due Date]])} -> 0 | J22: =Transactions[[#This Row],[Overdue Days]] -> 0
A23: T00069 | B23: ID0039 | C23: =VLOOKUP(B23,Data!$A$2:$B$101,2,0) -> Yvonne Morgan | D23: B00012 | E23: =VLOOKUP(D23,Data!$D$2:$E$121,2,0) -> Fine Benefit Must | F23: 45548 | G23: =Transactions[[#This Row],[Borrow Date]]+21 -> 45569 | H23: 45571 | I23: {=_xlfn.IFS(Transactions[[#This Row],[Return Date]]<=Transactions[[#This Row],[Due Date]],0,AND(Transactions[[#This Row],[Return Date]]="",TODAY()<=Transactions[[#This Row],[Due Date]]),0,Transactions[[#This Row],[Return Date]]>Transactions[[#This Row],[Due Date]],Transactions[[#This Row],[Return Date]]-Transactions[[#This Row],[Due Date]],AND(Transactions[[#This Row],[Return Date]]="",TODAY()>Transactions[[#This Row],[Due Date]]),TODAY()-Transactions[[#This Row],[Due Date]])} -> 2 | J23: =Transactions[[#This Row],[Overdue Days]] -> 2
A24: T00207 | B24: ID0085 | C24: =VLOOKUP(B24,Data!$A$2:$B$101,2,0) -> Christian Murphy | D24: B00012 | E24: =VLOOKUP(D24,Data!$D$2:$E$121,2,0) -> Fine Benefit Must | F24: 45419 | G24: =Transactions[[#This Row],[Borrow Date]]+21 -> 45440 | H24: 45443 | I24: {=_xlfn.IFS(Transactions[[#This Row],[Return Date]]<=Transactions[[#This Row],[Due Date]],0,AND(Transactions[[#This Row],[Return Date]]="",TODAY()<=Transactions[[#This Row],[Due Date]]),0,Transactions[[#This Row],[Return Date]]>Transactions[[#This Row],[Due Date]],Transactions[[#This Row],[Return Date]]-Transactions[[#This Row],[Due Date]],AND(Transactions[[#This Row],[Return Date]]="",TODAY()>Transactions[[#This Row],[Due Date]]),TODAY()-Transactions[[#This Row],[Due Date]])} -> 3 | J24: =Transactions[[#This Row],[Overdue Days]] -> 3
A25: T00299 | B25: ID0080 | C25: =VLOOKUP(B25,Data!$A$2:$B$101,2,0) -> Latoya Tucker | D25: B00012 | E25: =VLOOKUP(D25,Data!$D$2:$E$121,2,0) -> Fine Benefit Must | F25: 45436 | G25: =Transactions[[#This Row],[Borrow Date]]+21 -> 45457 | H25: 45462 | I25: {=_xlfn.IFS(Transactions[[#This Row],[Return Date]]<=Transactions[[#This Row],[Due Date]],0,AND(Transactions[[#This Row],[Return Date]]="",TODAY()<=Transactions[[#This Row],[Due Date]]),0,Transactions[[#This Row],[Return Date]]>Transactions[[#This Row],[Due Date]],Transactions[[#This Row],[Return Date]]-Transactions[[#This Row],[Due Date]],AND(Transactions[[#This Row],[Return Date]]="",TODAY()>Transactions[[#This Row],[Due Date]]),TODAY()-Transactions[[#This Row],[Due Date]])} -> 5 | J25: =Transactions[[#This Row],[Overdue Days]] -> 5
A26: T00107 | B26: ID0020 | C26: =VLOOKUP(B26,Data!$A$2:$B$101,2,0) -> Jesse Kennedy | D26: B00013 | E26: =VLOOKUP(D26,Data!$D$2:$E$121,2,0) -> Kitchen Inside | F26: 45598 | G26: =Transactions[[#This Row],[Borrow Date]]+21 -> 45619 | H26: 45623 | I26: {=_xlfn.IFS(Transactions[[#This Row],[Return Date]]<=Transactions[[#This Row],[Due Date]],0,AND(Transactions[[#This Row],[Return Date]]="",TODAY()<=Transactions[[#This Row],[Due Date]]),0,Transactions[[#This Row],[Return Date]]>Transactions[[#This Row],[Due Date]],Transactions[[#This Row],[Return Date]]-Transactions[[#This Row],[Due Date]],AND(Transactions[[#This Row],[Return Date]]="",TODAY()>Transactions[[#This Row],[Due Date]]),TODAY()-Transactions[[#This Row],[Due Date]])} -> 4 | J26: =Transactions[[#This Row],[Overdue Days]] -> 4
A27: T00147 | B27: ID0009 | C27: =VLOOKUP(B27,Data!$A$2:$B$101,2,0) -> Tracy Abbott | D27: B00014 | E27: =VLOOKUP(D27,Data!$D$2:$E$121,2,0) -> Image | F27: 45321 | G27: =Transactions[[#This Row],[Borrow Date]]+21 -> 45342 | H27: 45340 | I27: {=_xlfn.IFS(Transactions[[#This Row],[Return Date]]<=Transactions[[#This Row],[Due Date]],0,AND(Transactions[[#This Row],[Return Date]]="",TODAY()<=Transactions[[#This Row],[Due Date]]),0,Transactions[[#This Row],[Return Date]]>Transactions[[#This Row],[Due Date]],Transactions[[#This Row],[Return Date]]-Transactions[[#This Row],[Due Date]],AND(Transactions[[#This Row],[Return Date]]="",TODAY()>Transactions[[#This Row],[Due Date]]),TODAY()-Transactions[[#This Row],[Due Date]])} -> 0 | J27: =Transactions[[#This Row],[Overdue Days]] -> 0
A28: T00295 | B28: ID0014 | C28: =VLOOKUP(B28,Data!$A$2:$B$101,2,0) -> Joseph Barron | D28: B00014 | E28: =VLOOKUP(D28,Data!$D$2:$E$121,2,0) -> Image | F28: 45372 | G28: =Transactions[[#This Row],[Borrow Date]]+21 -> 45393 | H28: 45393 | I28: {=_xlfn.IFS(Transactions[[#This Row],[Return Date]]<=Transactions[[#This Row],[Due Date]],0,AND(Transactions[[#This Row],[Return Date]]="",TODAY()<=Transactions[[#This Row],[Due Date]]),0,Transactions[[#This Row],[Return Date]]>Transactions[[#This Row],[Due Date]],Transactions[[#This Row],[Return Date]]-Transactions[[#This Row],[Due Date]],AND(Transactions[[#This Row],[Return Date]]="",TODAY()>Transactions[[#This Row],[Due Date]]),TODAY()-Transactions[[#This Row],[Due Date]])} -> 0 | J28: =Transactions[[#This Row],[Overdue Days]] -> 0
A29: T00104 | B29: ID0062 | C29: =VLOOKUP(B29,Data!$A$2:$B$101,2,0) -> Kenneth Mitchell Jr. | D29: B00015 | E29: =VLOOKUP(D29,Data!$D$2:$E$121,2,0) -> Myself Owner | F29: 45495 | G29: =Transactions[[#This Row],[Borrow Date]]+21 -> 45516 | I29: {=_xlfn.IFS(Transactions[[#This Row],[Return Date]]<=Transactions[[#This Row],[Due Date]],0,AND(Transactions[[#This Row],[Return Date]]="",TODAY()<=Transactions[[#This Row],[Due Date]]),0,Transactions[[#This Row],[Return Date]]>Transactions[[#This Row],[Due Date]],Transactions[[#This Row],[Return Date]]-Transactions[[#This Row],[Due Date]],AND(Transactions[[#This Row],[Return Date]]="",TODAY()>Transactions[[#This Row],[Due Date]]),TODAY()-Transactions[[#This Row],[Due Date]])} -> 0 | J29: =Transactions[[#This Row],[Overdue Days]] -> 0
A30: T00117 | B30: ID0081 | C30: =VLOOKUP(B30,Data!$A$2:$B$101,2,0) -> Jeanette Cunningham | D30: B00015 | E30: =VLOOKUP(D30,Data!$D$2:$E$121,2,0) -> Myself Owner | F30: 45657 | G30: =Transactions[[#This Row],[Borrow Date]]+21 -> 45678 | I30: {=_xlfn.IFS(Transactions[[#This Row],[Return Date]]<=Transactions[[#This Row],[Due Date]],0,AND(Transactions[[#This Row],[Return Date]]="",TODAY()<=Transactions[[#This Row],[Due Date]]),0,Transactions[[#This Row],[Return Date]]>Transactions[[#This Row],[Due Date]],Transactions[[#This Row],[Return Date]]-Transactions[[#This Row],[Due Date]],AND(Transactions[[#This Row],[Return Date]]="",TODAY()>Transactions[[#This Row],[Due Date]]),TODAY()-Transactions[[#This Row],[Due Date]])} -> 0 | J30: =Transactions[[#This Row],[Overdue Days]] -> 0
A31: T00157 | B31: ID0082 | C31: =VLOOKUP(B31,Data!$A$2:$B$101,2,0) -> Joshua Ward | D31: B00015 | E31: =VLOOKUP(D31,Data!$D$2:$E$121,2,0) -> Myself Owner | F31: 45657 | G31: =Transactions[[#This Row],[Borrow Date]]+21 -> 45678 | I31: {=_xlfn.IFS(Transactions[[#This Row],[Return Date]]<=Transactions[[#This Row],[Due Date]],0,AND(Transactions[[#This Row],[Return Date]]="",TODAY()<=Transactions[[#This Row],[Due Date]]),0,Transactions[[#This Row],[Return Date]]>Transactions[[#This Row],[Due Date]],Transactions[[#This Row],[Return Date]]-Transactions[[#This Row],[Due Date]],AND(Transactions[[#This Row],[Return Date]]="",TODAY()>Transactions[[#This Row],[Due Date]]),TODAY()-Transactions[[#This Row],[Due Date]])} -> 0 | J31: =Transactions[[#This Row],[Overdue Days]] -> 0
A32: T00057 | B32: ID0075 | C32: =VLOOKUP(B32,Data!$A$2:$B$101,2,0) -> Jennifer Robinson | D32: B00016 | E32: =VLOOKUP(D32,Data!$D$2:$E$121,2,0) -> Car Without Now | F32: 45352 | G32: =Transactions[[#This Row],[Borrow Date]]+21 -> 45373 | H32: 45368 | I32: {=_xlfn.IFS(Transactions[[#This Row],[Return Date]]<=Transactions[[#This Row],[Due Date]],0,AND(Transactions[[#This Row],[Return Date]]="",TODAY()<=Transactions[[#This Row],[Due Date]]),0,Transactions[[#This Row],[Return Date]]>Transactions[[#This Row],[Due Date]],Transactions[[#This Row],[Return Date]]-Transactions[[#This Row],[Due Date]],AND(Transactions[[#This Row],[Return Date]]="",TODAY()>Transactions[[#This Row],[Due Date]]),TODAY()-Transactions[[#This Row],[Due Date]])} -> 0 | J32: =Transactions[[#This Row],[Overdue Days]] -> 0
A33: T00263 | B33: ID0073 | C33: =VLOOKUP(B33,Data!$A$2:$B$101,2,0) -> Nancy Day | D33: B00016 | E33: =VLOOKUP(D33,Data!$D$2:$E$121,2,0) -> Car Without Now | F33: 45540 | G33: =Transactions[[#This Row],[Borrow Date]]+21 -> 45561 | H33: 45555 | I33: {=_xlfn.IFS(Transactions[[#This Row],[Return Date]]<=Transactions[[#This Row],[Due Date]],0,AND(Transactions[[#This Row],[Return Date]]="",TODAY()<=Transactions[[#This Row],[Due Date]]),0,Transactions[[#This Row],[Return Date]]>Transactions[[#This Row],[Due Date]],Transactions[[#This Row],[Return Date]]-Transactions[[#This Row],[Due Date]],AND(Transactions[[#This Row],[Return Date]]="",TODAY()>Transactions[[#This Row],[Due Date]]),TODAY()-Transactions[[#This Row],[Due Date]])} -> 0 | J33: =Transactions[[#This Row],[Overdue Days]] -> 0
A34: T00036 | B34: ID0089 | C34: =VLOOKUP(B34,Data!$A$2:$B$101,2,0) -> Edward Price | D34: B00017 | E34: =VLOOKUP(D34,Data!$D$2:$E$121,2,0) -> Simply Mother | F34: 45551 | G34: =Transactions[[#This Row],[Borrow Date]]+21 -> 45572 | H34: 45576 | I34: {=_xlfn.IFS(Transactions[[#This Row],[Return Date]]<=Transactions[[#This Row],[Due Date]],0,AND(Transactions[[#This Row],[Return Date]]="",TODAY()<=Transactions[[#This Row],[Due Date]]),0,Transactions[[#This Row],[Return Date]]>Transactions[[#This Row],[Due Date]],Transactions[[#This Row],[Return Date]]-Transactions[[#This Row],[Due Date]],AND(Transactions[[#This Row],[Return Date]]="",TODAY()>Transactions[[#This Row],[Due Date]]),TODAY()-Transactions[[#This Row],[Due Date]])} -> 4 | J34: =Transactions[[#This Row],[Overdue Days]] -> 4
A35: T00211 | B35: ID0091 | C35: =VLOOKUP(B35,Data!$A$2:$B$101,2,0) -> Tracy Peters | D35: B00017 | E35: =VLOOKUP(D35,Data!$D$2:$E$121,2,0) -> Simply Mother | F35: 45400 | G35: =Transactions[[#This Row],[Borrow Date]]+21 -> 45421 | H35: 45418 | I35: {=_xlfn.IFS(Transactions[[#This Row],[Return Date]]<=Transactions[[#This Row],[Due Date]],0,AND(Transactions[[#This Row],[Return Date]]="",TODAY()<=Transactions[[#This Row],[Due Date]]),0,Transactions[[#This Row],[Return Date]]>Transactions[[#This Row],[Due Date]],Transactions[[#This Row],[Return Date]]-Transactions[[#This Row],[Due Date]],AND(Transactions[[#This Row],[Return Date]]="",TODAY()>Transactions[[#This Row],[Due Date]]),TODAY()-Transactions[[#This Row],[Due Date]])} -> 0 | J35: =Transactions[[#This Row],[Overdue Days]] -> 0
A36: T00220 | B36: ID0017 | C36: =VLOOKUP(B36,Data!$A$2:$B$101,2,0) -> Katelyn Flores | D36: B00018 | E36: =VLOOKUP(D36,Data!$D$2:$E$121,2,0) -> Dark Such Hour Argue | F36: 45549 | G36: =Transactions[[#This Row],[Borrow Date]]+21 -> 45570 | H36: 45567 | I36: {=_xlfn.IFS(Transactions[[#This Row],[Return Date]]<=Transactions[[#This Row],[Due Date]],0,AND(Transactions[[#This Row],[Return Date]]="",TODAY()<=Transactions[[#This Row],[Due Date]]),0,Transactions[[#This Row],[Return Date]]>Transactions[[#This Row],[Due Date]],Transactions[[#This Row],[Return Date]]-Transactions[[#This Row],[Due Date]],AND(Transactions[[#This Row],[Return Date]]="",TODAY()>Transactions[[#This Row],[Due Date]]),TODAY()-Transactions[[#This Row],[Due Date]])} -> 0 | J36: =Transactions[[#This Row],[Overdue Days]] -> 0
A37: T00224 | B37: ID0017 | C37: =VLOOKUP(B37,Data!$A$2:$B$101,2,0) -> Katelyn Flores | D37: B00018 | E37: =VLOOKUP(D37,Data!$D$2:$E$121,2,0) -> Dark Such Hour Argue | F37: 45599 | G37: =Transactions[[#This Row],[Borrow Date]]+21 -> 45620 | H37: 45620 | I37: {=_xlfn.IFS(Transactions[[#This Row],[Return Date]]<=Transactions[[#This Row],[Due Date]],0,AND(Transactions[[#This Row],[Return Date]]="",TODAY()<=Transactions[[#This Row],[Due Date]]),0,Transactions[[#This Row],[Return Date]]>Transactions[[#This Row],[Due Date]],Transactions[[#This Row],[Return Date]]-Transactions[[#This Row],[Due Date]],AND(Transactions[[#This Row],[Return Date]]="",TODAY()>Transactions[[#This Row],[Due Date]]),TODAY()-Transactions[[#This Row],[Due Date]])} -> 0 | J37: =Transactions[[#This Row],[Overdue Days]] -> 0
A38: T00021 | B38: ID0004 | C38: =VLOOKUP(B38,Data!$A$2:$B$101,2,0) -> Tina Willis | D38: B00019 | E38: =VLOOKUP(D38,Data!$D$2:$E$121,2,0) -> Firm Write Population | F38: 45319 | G38: =Transactions[[#This Row],[Borrow Date]]+21 -> 45340 | H38: 45340 | I38: {=_xlfn.IFS(Transactions[[#This Row],[Return Date]]<=Transactions[[#This Row],[Due Date]],0,AND(Transactions[[#This Row],[Return Date]]="",TODAY()<=Transactions[[#This Row],[Due Date]]),0,Transactions[[#This Row],[Return Date]]>Transactions[[#This Row],[Due Date]],Transactions[[#This Row],[Return Date]]-Transactions[[#This Row],[Due Date]],AND(Transactions[[#This Row],[Return Date]]="",TODAY()>Transactions[[#This Row],[Due Date]]),TODAY()-Transactions[[#This Row],[Due Date]])} -> 0 | J38: =Transactions[[#This Row],[Overdue Days]] -> 0
A39: T00044 | B39: ID0058 | C39: =VLOOKUP(B39,Data!$A$2:$B$101,2,0) -> Amy Shaw | D39: B00019 | E39: =VLOOKUP(D39,Data!$D$2:$E$121,2,0) -> Firm Write Population | F39: 45653 | G39: =Transactions[[#This Row],[Borrow Date]]+21 -> 45674 | I39: {=_xlfn.IFS(Transactions[[#This Row],[Return Date]]<=Transactions[[#This Row],[Due Date]],0,AND(Transactions[[#This Row],[Return Date]]="",TODAY()<=Transactions[[#This Row],[Due Date]]),0,Transactions[[#This Row],[Return Date]]>Transactions[[#This Row],[Due Date]],Transactions[[#This Row],[Return Date]]-Transactions[[#This Row],[Due Date]],AND(Transactions[[#This Row],[Return Date]]="",TODAY()>Transactions[[#This Row],[Due Date]]),TODAY()-Transactions[[#This Row],[Due Date]])} -> #VALUE! | J39: =Transactions[[#This Row],[Overdue Days]] -> #VALUE!
A40: T00186 | B40: ID0032 | C40: =VLOOKUP(B40,Data!$A$2:$B$101,2,0) -> Jason Oconnor | D40: B00019 | E40: =VLOOKUP(D40,Data!$D$2:$E$121,2,0) -> Firm Write Population | F40: 45523 | G40: =Transactions[[#This Row],[Borrow Date]]+21 -> 45544 | H40: 45548 | I40: {=_xlfn.IFS(Transactions[[#This Row],[Return Date]]<=Transactions[[#This Row],[Due Date]],0,AND(Transactions[[#This Row],[Return Date]]="",TODAY()<=Transactions[[#This Row],[Due Date]]),0,Transactions[[#This Row],[Return Date]]>Transactions[[#This Row],[Due Date]],Transactions[[#This Row],[Return Date]]-Transactions[[#This Row],[Due Date]],AND(Transactions[[#This Row],[Return Date]]="",TODAY()>Transactions[[#This Row],[Due Date]]),TODAY()-Transactions[[#This Row],[Due Date]])} -> 4 | J40: =Transactions[[#This Row],[Overdue Days]] -> 4
...
